<?xml version="1.0"?>
<robot name="mira">
    <material name="White">
      <color rgba="1 1 1 1"/>
    </material>
    <material name="ClearWhite">
      <color rgba="1 1 1 0.1"/>
    </material>
    <material name="Red">
        <color rgba="1 0.0 0.0 1.0"/>
    </material>
    <material name="Green">
      <color rgba="0 1.0 0.0 1"/>
    </material>
    <material name="Blue">
        <color rgba="0.0 0.0 1.0 1.0"/>
    </material>
    <material name="Black">
        <color rgba="0 0.0 0.0 1.0"/>
    </material>
    <material name="ClearBlack">
        <color rgba="0 0.0 0.0 0.1"/>
    </material>
    <material name="HotPink">
        <color rgba="1 0.4 0.7 1.0"/>
    </material>
    <link name="base_link">
        <visual>
            <origin rpy="0 0 0" xyz="0 0 0"/>
            <geometry>
                <cylinder radius="0.06" length="0.09"/>
            </geometry>
            <material name="White"/>
        </visual>
    </link>
    <link name="roll_M1_link">
        <visual>
            <origin rpy="1.57 0 0" xyz="0 0 0"/>
            <geometry>
                <cylinder radius="0.01" length="0.005"/>
            </geometry>
            <material name="Red"/>
        </visual>
    </link>
    <link name="pitch_M2_link">
        <visual>
            <origin rpy="0 1.57 0" xyz="0 0 0"/>
            <geometry>
                <cylinder radius="0.01" length="0.005"/>
            </geometry>
            <material name="Green"/>
        </visual>
    </link>
    <link name="yaw_M3_link">
        <visual>
            <origin rpy="0 0 1.57" xyz="0 0 0"/>
            <geometry>
                <cylinder radius="0.01" length="0.005"/>
            </geometry>
            <material name="Blue"/>
        </visual>
    </link>
    <link name="head_link">
        <visual>
            <origin rpy="0 0 0" xyz="0 0 0"/>
            <geometry>
                <sphere radius="0.06"/>
            </geometry>
            <material name="ClearWhite"/>
        </visual>
    </link>
    <link name="left_eye_link">
        <visual>
            <origin rpy="0 0 0" xyz="0 0 0"/>
            <geometry>
                <cylinder radius="0.00525" length="0.00525" />
            </geometry>
            <material name="Black"/>
        </visual>
    </link>
    <link name="right_eye_link">
        <visual>
            <origin rpy="0 0 0" xyz="0 0 0"/>
            <geometry>
                <cylinder radius="0.00525" length="0.00525" />
            </geometry>
            <material name="Black"/>
        </visual>
    </link>
    <joint name="roll_joint" type="revolute">
        <parent link="base_link"/>
        <child link="roll_M1_link"/>
        <origin xyz="0 0 0.08" rpy="0 0 0"/>
        <limit lower="-0.2" upper="0.2" effort="0.1" velocity="0.005"/>
        <axis xyz="1 0 0"/>
    </joint>
    <joint name="pitch_joint" type="revolute">
        <parent link="roll_M1_link"/>
        <child link="pitch_M2_link"/>
        <origin xyz="0 0 0" rpy="0 0 0"/>
        <limit lower="-0.2" upper="0.2" effort="0.1" velocity="0.005"/>
        <axis xyz="0 1 0"/>
    </joint>
    <joint name="yaw_joint" type="revolute">
        <parent link="pitch_M2_link"/>
        <child link="yaw_M3_link"/>
        <origin xyz="0 0 0" rpy="0 0 0"/>
        <limit lower="-0.2" upper="0.2" effort="0.1" velocity="0.005"/>
        <axis xyz="0 0 1"/>
    </joint>
    <joint name="base_head_joint" type="fixed">
        <parent link="yaw_M3_link"/>
        <child link="head_link"/>
        <origin xyz="0 0 0" rpy="0 0 0"/>
    </joint>
    <joint name="head_lefteye_joint" type="fixed">
        <parent link="head_link"/>
        <child link="left_eye_link"/>
        <origin xyz="0.06 0.01 0" rpy="0 0 0"/>
    </joint>
    <joint name="head_righteye_joint" type="fixed">
        <parent link="head_link"/>
        <child link="right_eye_link"/>
        <origin xyz="0.06 -0.01 0" rpy="0 0 0"/>
    </joint>
  
</robot>