<?xml version="1.0"?>
<robot name="mira">
    <material name="White">
      <color rgba="1 1 1 1"/>
    </material>
    <material name="ClearWhite">
      <color rgba="1 1 1 0.1"/>
    </material>
    <material name="Red">
        <color rgba="1 0.0 0.0 1.0"/>
    </material>
    <material name="Green">
      <color rgba="0 1.0 0.0 1"/>
    </material>
    <material name="Blue">
        <color rgba="0.0 0.0 1.0 1.0"/>
    </material>
    <material name="Black">
        <color rgba="0 0.0 0.0 1.0"/>
    </material>
    <material name="ClearBlack">
        <color rgba="0 0.0 0.0 0.1"/>
    </material>
    <material name="HotPink">
        <color rgba="1 0.4 0.7 1.0"/>
    </material>
    <link name="base_link">
    </link>
    <link name="body_link">
        <inertial>
            <origin xyz="0 0 0" rpy="0 0 0"/>
            <mass value="0.18" />
            <inertia ixx="0.0002835" ixy="0.0" ixz="0.0" iyy="0.0002835" iyz="0.0" izz="0.000324"/>
        </inertial>
        <collision>
            <origin xyz="0 0 0" rpy="0 0 0"/>
            <geometry>
                <cylinder radius="0.06" length="0.09"/>
            </geometry>
        </collision>
        <visual>
            <origin rpy="0 0 0" xyz="0 0 0"/>
            <geometry>
                <mesh filename="package://my_mira_description/models/mira/meshes/mira_body_v3.dae"/>
            </geometry>
        </visual>
        <gazebo reference="body_link">
            <kp>100000.0</kp>
            <kd>100000.0</kd>
            <mu1>10.0</mu1>
            <mu2>10.0</mu2>
            <material>Gazebo/Grey</material>
        </gazebo>
    </link>
    <link name="roll_M1_link">
        <visual>
            <origin rpy="1.57 0 0" xyz="0 0 0"/>
            <geometry>
                <cylinder radius="0.01" length="0.005"/>
            </geometry>
            <material name="Red"/>
        </visual>
        <inertial>
            <origin xyz="0 0 0" rpy="0 0 0"/>
            <mass value="0.001" />
            <inertia ixx="2.7083333333333334e-08" ixy="0.0" ixz="0.0" iyy="2.7083333333333334e-08" iyz="0.0" izz="5.0000000000000004e-08"/>-->
        </inertial>
        <gazebo reference="roll_M1_link">
            <kp>100000.0</kp>
            <kd>100000.0</kd>
            <mu1>10.0</mu1>
            <mu2>10.0</mu2>
            <material>Gazebo/Red</material>
        </gazebo>
    </link>
    <link name="pitch_M2_link">
        <visual>
            <origin rpy="0 1.57 0" xyz="0 0 0"/>
            <geometry>
                <cylinder radius="0.01" length="0.005"/>
            </geometry>
            <material name="Green"/>
        </visual>
        <inertial>
            <origin xyz="0 0 0" rpy="0 0 0"/>
            <mass value="0.001" />
            <inertia ixx="2.7083333333333334e-08" ixy="0.0" ixz="0.0" iyy="2.7083333333333334e-08" iyz="0.0" izz="5.0000000000000004e-08"/>
        </inertial>
        <gazebo reference="pitch_M2_link">
            <kp>100000.0</kp>
            <kd>100000.0</kd>
            <mu1>10.0</mu1>
            <mu2>10.0</mu2>
            <material>Gazebo/Green</material>
        </gazebo>
    </link>
    <link name="yaw_M3_link">
        <visual>
            <origin rpy="0 0 1.57" xyz="0 0 0"/>
            <geometry>
                <cylinder radius="0.01" length="0.005"/>
            </geometry>
            <material name="Blue"/>
        </visual>
        <inertial>
            <origin xyz="0 0 0" rpy="0 0 0"/>
            <mass value="0.001" />
            <inertia ixx="2.7083333333333334e-08" ixy="0.0" ixz="0.0" iyy="2.7083333333333334e-08" iyz="0.0" izz="5.0000000000000004e-08"/>
        </inertial>
        <gazebo reference="yaw_M3_link">
            <kp>100000.0</kp>
            <kd>100000.0</kd>
            <mu1>10.0</mu1>
            <mu2>10.0</mu2>
            <material>Gazebo/Blue</material>
        </gazebo>
    </link>
    <link name="head_link">
        <visual>
            <origin rpy="0 0 0" xyz="0 0 0"/>
            <geometry>
                <mesh filename="package://my_mira_description/models/mira/meshes/mira_head_v5.dae"/>
            </geometry>
        </visual>
        <inertial>
            <origin xyz="0 0 0" rpy="0 0 0"/>
            <mass value="0.02" />
            <!-- Ix,y,z = 2.8800000000000002e-05 -->
            <inertia ixx="2.8800000000000002e-05" ixy="0.0" ixz="0.0" iyy="2.8800000000000002e-05" iyz="0.0" izz="2.8800000000000002e-05"/>
        </inertial>
        <gazebo reference="head_link">
            <kp>100000.0</kp>
            <kd>100000.0</kd>
            <mu1>10.0</mu1>
            <mu2>10.0</mu2>
            <material>Gazebo/Grey</material>
        </gazebo>
    </link>
    <link name="left_eye_link">
        <visual>
            <origin rpy="0 0 0" xyz="0 0 0"/>
            <geometry>
                <mesh filename="package://my_mira_description/models/mira/meshes/mira_eye_v4.dae"/>
            </geometry>
        </visual>
        <gazebo reference="left_eye_link">
            <kp>100000.0</kp>
            <kd>100000.0</kd>
            <mu1>10.0</mu1>
            <mu2>10.0</mu2>
            <material>Gazebo/Black</material>
        </gazebo>
    </link>
    <link name="right_eye_link">
        <visual>
            <origin rpy="0 0 0" xyz="0 0 0"/>
            <geometry>
                <mesh filename="package://my_mira_description/models/mira/meshes/mira_eye_v4.dae"/>
            </geometry>
        </visual>
        <gazebo reference="right_eye_link">
            <kp>100000.0</kp>
            <kd>100000.0</kd>
            <mu1>10.0</mu1>
            <mu2>10.0</mu2>
            <material>Gazebo/Black</material>
        </gazebo>
    </link>
    <joint name="base_body_joint" type="fixed">
        <parent link="base_link"/>
        <child link="body_link"/>
        <origin xyz="0 0 0" rpy="0 0 0"/>
    </joint>
    <joint name="roll_joint" type="revolute">
        <parent link="body_link"/>
        <child link="roll_M1_link"/>
        <origin xyz="0 0 0.03" rpy="0 0 0"/>
        <limit lower="-0.2" upper="0.2" effort="0.1" velocity="0.005"/>
        <axis xyz="1 0 0"/>
    </joint>
    <joint name="pitch_joint" type="revolute">
        <parent link="roll_M1_link"/>
        <child link="pitch_M2_link"/>
        <origin xyz="0 0 0" rpy="0 0 0"/>
        <limit lower="-0.2" upper="0.2" effort="0.1" velocity="0.005"/>
        <axis xyz="0 1 0"/>
    </joint>
    <joint name="yaw_joint" type="revolute">
        <parent link="pitch_M2_link"/>
        <child link="yaw_M3_link"/>
        <origin xyz="0 0 0" rpy="0 0 0"/>
        <limit lower="-0.2" upper="0.2" effort="0.1" velocity="0.005"/>
        <axis xyz="0 0 1"/>
    </joint>
    <joint name="base_head_joint" type="fixed">
        <parent link="yaw_M3_link"/>
        <child link="head_link"/>
        <origin xyz="0 0 0" rpy="0 0 1.57"/>
    </joint>
    <joint name="head_lefteye_joint" type="fixed">
        <parent link="head_link"/>
        <child link="left_eye_link"/>
        <origin xyz="-0.01 0.06 0.008" rpy="1.57 0 0"/>
    </joint>
    <joint name="head_righteye_joint" type="fixed">
        <parent link="head_link"/>
        <child link="right_eye_link"/>
        <origin xyz="0.01 0.06 0.008" rpy="1.57 0 0"/>
    </joint>
</robot>